<?xml version="2.0"?>
<!-- Revolute-Revolute Manipulator -->
<robot name="ebs_tractor" xmlns:xacro="http://www.ros.org/wiki/xacro">

  <!-- Constants for robot dimensions -->
  <xacro:property name="PI" value="3.1415926535897931"/>
  <xacro:property name="mass" value="1" /> <!-- arbitrary value for mass -->
  <xacro:property name="width" value="1"/>

   <!-- Import all Gazebo-customization elements, including Gazebo colors -->
  <xacro:include filename="$(find ebs_description)/urdf/ebs_tractor.gazebo" />
  <!-- Import Rviz colors -->
  <xacro:include filename="$(find ebs_description)/urdf/materials.xacro" />

  <!-- Base Link -->
  <link name="base_link">
    <collision>
      <origin xyz="0 0 0.4" rpy="0 0 0"/>
        <geometry>
	        <box size="1 1.5 0.5"/>
        </geometry>
    </collision>

    <visual>
      <origin xyz="0 0 0.4" rpy="0 0 0"/>
      <geometry>
	      <box size="1 1.5 0.5"/>
      </geometry>
      <material name="orange"/>
    </visual>
  </link>

  <link name="right_caster">
    <collision>
      <origin xyz="0.5 -0.75 0.15" rpy="0 0 0"/>
        <geometry>
          <sphere radius="0.15"/>
        </geometry>
    </collision>

    <visual>
      <origin xyz="0.5 -0.75 0.15" rpy="0 0 0"/>
      <geometry>
        <sphere radius="0.15"/>
      </geometry>
      <material name="black"/>
    </visual>
    <inertial>
        <origin xyz="0 0 0" rpy="0 0 0" />
        <mass value="3" />
        <inertia
          ixx="0.1" ixy="0.0" ixz="0.0"
          iyy="0.1" iyz="0.0"
          izz="0.1" />
    </inertial>
  </link>

  <link name="left_caster">
    <collision>
      <origin xyz="-0.5 -0.75 0.15" rpy="0 0 0"/>
        <geometry>
          <sphere radius="0.15"/>
        </geometry>
    </collision>

    <visual>
      <origin xyz="-0.5 -0.75 0.15" rpy="0 0 0"/>
      <geometry>
        <sphere radius="0.15"/>
      </geometry>
      <material name="black"/>
    </visual>

    <inertial>
        <origin xyz="0 0 0" rpy="0 0 0" />
        <mass value="3" />
        <inertia
          ixx="0.1" ixy="0.0" ixz="0.0"
          iyy="0.1" iyz="0.0"
          izz="0.1" />
    </inertial>
  </link>

  <joint name="base_to_right_caster" type="fixed">
    <parent link="base_link"/>
    <child link="right_caster"/>
  </joint>

  <joint name="base_to_left_caster" type="fixed">
    <parent link="base_link"/>
    <child link="left_caster"/>
  </joint>

  <link name="steering_wheel">
    <collision>
      <origin xyz="0 0 0" rpy="0 0 0"/>
        <geometry>
          <cylinder length="0.5" radius="0.25"/>
        </geometry>
    </collision>

    <visual>
      <origin xyz="0 0 0" rpy="0 0 0"/>
        <geometry>
          <cylinder length="0.5" radius="0.25"/>
        </geometry>
      <material name="orange"/>
    </visual>

    <inertial>
        <origin xyz="0 0 0" rpy="0 0 0" />
        <mass value="1" />
        <inertia
          ixx="0" ixy="0.0" ixz="0.0"
          iyy="0" iyz="0.0"
          izz="0" />
    </inertial>
  </link>

  <joint name="steering_joint" type="revolute">
    <parent link="base_link"/>
    <child link="steering_wheel"/>
    <axis xyz="0 0 1"/>
    <origin xyz="0 0.75 0.4" rpy="0 0 0"/>
    <limit lower="-0.523599" upper="0.523599" effort="1000.0" velocity="10"/>
  </joint>

  <link name="main_wheel">
    <collision>
      <origin xyz="0 0 0" rpy="0 ${pi/2} 0"/>
        <geometry>
          <cylinder length="0.05" radius="0.15"/>
        </geometry>
    </collision>

    <visual>
      <origin xyz="0 0 0" rpy="0 ${pi/2} 0"/>
        <geometry>
          <cylinder length="0.05" radius="0.15"/>
        </geometry>
      <material name="white"/>
    </visual>

    <inertial>
        <origin xyz="0 0 0" rpy="0 0 0" />
        <mass value="1" />
        <inertia
          ixx="1" ixy="0.0" ixz="0.0"
          iyy="1" iyz="0.0"
          izz="1" />
    </inertial>
  </link>

  <joint name="velocity_joint" type="continuous">
    <parent link="steering_wheel"/>
    <child link="main_wheel"/>
    <axis xyz="1 0 0"/>
    <origin xyz="0 0 -0.25" rpy="0 0 0"/>
  </joint>

  <link name="hokuyo_link">
    <collision>
      <origin xyz="0 0 0" rpy="0 0 0"/>
      <geometry>
	      <box size="0.1 0.1 0.1"/>
      </geometry>
    </collision>

    <visual>
      <origin xyz="0 0 0" rpy="0 0 0"/>
      <geometry>
        <mesh filename="package://ebs_description/meshes/hokuyo.dae"/>
      </geometry>
    </visual>

    <inertial>
      <mass value="1e-5" />
      <origin xyz="0 0 0" rpy="0 0 0"/>
      <inertia ixx="1e-6" ixy="0" ixz="0" iyy="1e-6" iyz="0" izz="1e-6" />
    </inertial>
  </link>

  <joint name="hokuyo_joint" type="fixed">
    <axis xyz="0 1 0" />
    <origin xyz="0 0 0.67" rpy="0 0 1.570796326"/>
    <parent link="base_link"/>
    <child link="hokuyo_link"/>
  </joint>

  <transmission name="steering">
    <type>transmission_interface/SimpleTransmission</type>
    <joint name="steering_joint">
      <hardwareInterface>hardware_interface/EffortJointInterface</hardwareInterface>
    </joint>
    <actuator name="motor1">
      <hardwareInterface>hardware_interface/EffortJointInterface</hardwareInterface>
      <mechanicalReduction>1</mechanicalReduction>
    </actuator>
  </transmission>

  <transmission name="velocity">
    <type>transmission_interface/SimpleTransmission</type>
    <joint name="velocity_joint">
      <hardwareInterface>hardware_interface/VelocityJointInterface</hardwareInterface>
    </joint>
    <actuator name="motor2">
      <hardwareInterface>hardware_interface/VelocityJointInterface</hardwareInterface>
      <mechanicalReduction>1</mechanicalReduction>
    </actuator>
  </transmission>

</robot>
