<?xml version='1.0'?>
<sdf version='1.4'>
  <model name="EBS_tractor">
    <static>false</static>
    <include>
      <uri>model://hokuyo</uri>
      <pose>0 0 0.67 0 0 1.5707</pose>
    </include>
    <link name='chassis'>
      <pose>0 0 0.4 0 0 0</pose>
      <collision name='collision'>
        <geometry>
          <box>
            <size>1 1.5 0.5</size>
          </box>
        </geometry>
      </collision>
      <visual name='visual'>
          <geometry>
            <box>
              <size>1 1.5 0.5</size>
            </box>
          </geometry>
      </visual>

      <collision name='right_caster_collision'>
        <pose>0.5 -0.75 -0.25 0 0 0</pose>
        <geometry>
            <sphere>
            <radius>.15</radius>
          </sphere>
        </geometry>

        <surface>
          <friction>
            <ode>
              <mu>0</mu>
              <mu2>0</mu2>
              <slip1>1.0</slip1>
              <slip2>1.0</slip2>
            </ode>
          </friction>
        </surface>
      </collision>

      <visual name='right_visual'>
        <pose>0.5 -0.75 -0.25 0 0 0</pose>
        <geometry>
            <sphere>
            <radius>.15</radius>
          </sphere>
        </geometry>
      </visual>

      <collision name='left_caster_collision'>
        <pose>-0.5 -0.75 -0.25 0 0 0</pose>
        <geometry>
            <sphere>
            <radius>.15</radius>
          </sphere>
        </geometry>

        <surface>
          <friction>
            <ode>
              <mu>0.1</mu>
              <mu2>0.1</mu2>
              <slip1>1.0</slip1>
              <slip2>1.0</slip2>
            </ode>
          </friction>
        </surface>
      </collision>

      <visual name='left_visual'>
        <pose>-0.5 -0.75 -0.25 0 0 0</pose>
        <geometry>
            <sphere>
            <radius>.15</radius>
          </sphere>
        </geometry>
      </visual>
    </link>
    <link name="main_wheel">
      <pose>0 0.75 0.15 0 1.5707 0</pose>
      <collision name="collision">
        <geometry>
          <cylinder>
            <radius>.15</radius>
            <length>.05</length>
          </cylinder>
        </geometry>
      </collision>
      <visual name="visual">
        <geometry>
          <cylinder>
            <radius>.15</radius>
            <length>.05</length>
          </cylinder>
        </geometry>
      </visual>
    </link>
    <link name="steering_wheel">
      <pose>0 0.75 0.4 0 0 0</pose>
      <collision name="collision">
        <geometry>
          <cylinder>
            <radius>.25</radius>
            <length>.5</length>
          </cylinder>
        </geometry>
      </collision>
      <visual name="visual">
        <geometry>
          <cylinder>
            <radius>.25</radius>
            <length>.5</length>
          </cylinder>
        </geometry>
      </visual>
    </link>
    <joint type="revolute" name="wheel_speed">
      <pose>0 0 0 0 0 0</pose>
      <child>main_wheel</child>
      <parent>steering_wheel</parent>
      <axis>
        <xyz>-1 0 0</xyz>
      </axis>
    </joint>
    <joint type="revolute" name="turn_angle">
      <pose>0 0 0 0 0 0</pose>
      <child>steering_wheel</child>
      <parent>chassis</parent>
      <axis>
          <limit>
            <lower>-0.52356</lower>
            <upper>0.5236</upper>
          </limit>
        <xyz>0 0 1</xyz>
      </axis>
    </joint>
    <joint name="hokuyo_joint" type="fixed">
      <child>hokuyo::link</child>
      <parent>chassis</parent>
    </joint>
  </model>
</sdf>
